Workbook

Sheet Dashboard
H1: Number of sections at stage | P1: Number of sections at stage
B2: KPI | C2: Cumulative | D2: Percentage of total | F2: Chapter | G2: Name | H2: Early stages | I2: Ready for review 1 | J2: Review 1 completed | K2: Ready for review 2 | L2: Review 2 completed | M2: Finished | O2: Pilot | P2: In early stages | Q2: Ready for review 1 | R2: Review 1 completed | S2: Ready for review 2 | T2: Review 2 completed | U2: Finished
B3: Total sections | C3: =COUNTA(Table1[Sec.Name]) -> 96 | D3: =C3/$C$3 -> 1 | F3: 1 | G3: =INDEX(Table1[Ch.Name],MATCH(Dashboard!$F3,Table1[Chapter],0)) -> Numbers and coordinate systems | H3: {=IFERROR(INDEX('Pivot Chapters'!$B$5:$H$18,MATCH(Dashboard!$G3,'Pivot Chapters'!$A$5:$A$18,0),_xlfn.XMATCH(Dashboard!H$2,'Pivot Chapters'!$B$4:$H$4,0,1)),0)} -> 0 | I3: {=IFERROR(INDEX('Pivot Chapters'!$B$5:$H$18,MATCH(Dashboard!$G3,'Pivot Chapters'!$A$5:$A$18,0),_xlfn.XMATCH(Dashboard!I$2,'Pivot Chapters'!$B$4:$H$4,0,1)),0)} -> 1 | J3: {=IFERROR(INDEX('Pivot Chapters'!$B$5:$H$18,MATCH(Dashboard!$G3,'Pivot Chapters'!$A$5:$A$18,0),_xlfn.XMATCH(Dashboard!J$2,'Pivot Chapters'!$B$4:$H$4,0,1)),0)} -> 3 | K3: {=IFERROR(INDEX('Pivot Chapters'!$B$5:$H$18,MATCH(Dashboard!$G3,'Pivot Chapters'!$A$5:$A$18,0),_xlfn.XMATCH(Dashboard!K$2,'Pivot Chapters'!$B$4:$H$4,0,1)),0)} -> 0 | L3: {=IFERROR(INDEX('Pivot Chapters'!$B$5:$H$18,MATCH(Dashboard!$G3,'Pivot Chapters'!$A$5:$A$18,0),_xlfn.XMATCH(Dashboard!L$2,'Pivot Chapters'!$B$4:$H$4,0,1)),0)} -> 0 | M3: {=IFERROR(INDEX('Pivot Chapters'!$B$5:$H$18,MATCH(Dashboard!$G3,'Pivot Chapters'!$A$5:$A$18,0),_xlfn.XMATCH(Dashboard!M$2,'Pivot Chapters'!$B$4:$H$4,0,1)),0)} -> 0 | O3: A | P3: {=IFERROR(INDEX('Pivot Pilots'!$B$5:$H$7,MATCH($O3,'Pivot Pilots'!$A$5:$A$6,0),_xlfn.XMATCH(P$2,'Pivot Pilots'!$B$4:$H$4,0,1)),0)} -> 0 | Q3: {=IFERROR(INDEX('Pivot Pilots'!$B$5:$H$7,MATCH($O3,'Pivot Pilots'!$A$5:$A$6,0),_xlfn.XMATCH(Q$2,'Pivot Pilots'!$B$4:$H$4,0,1)),0)} -> 0 | R3: {=IFERROR(INDEX('Pivot Pilots'!$B$5:$H$7,MATCH($O3,'Pivot Pilots'!$A$5:$A$6,0),_xlfn.XMATCH(R$2,'Pivot Pilots'!$B$4:$H$4,0,1)),0)} -> 10 | S3: {=IFERROR(INDEX('Pivot Pilots'!$B$5:$H$7,MATCH($O3,'Pivot Pilots'!$A$5:$A$6,0),_xlfn.XMATCH(S$2,'Pivot Pilots'!$B$4:$H$4,0,1)),0)} -> 12 | T3: {=IFERROR(INDEX('Pivot Pilots'!$B$5:$H$7,MATCH($O3,'Pivot Pilots'!$A$5:$A$6,0),_xlfn.XMATCH(T$2,'Pivot Pilots'!$B$4:$H$4,0,1)),0)} -> 0 | U3: {=IFERROR(INDEX('Pivot Pilots'!$B$5:$H$7,MATCH($O3,'Pivot Pilots'!$A$5:$A$6,0),_xlfn.XMATCH(U$2,'Pivot Pilots'!$B$4:$H$4,0,1)),0)} -> 1
B4: Ready for review 1 | C4: =COUNTIF(Table1[Ready for review 1],"Yes") -> 52 | D4: =C4/$C$3 -> 0.54166667 | F4: 2 | G4: =INDEX(Table1[Ch.Name],MATCH(Dashboard!$F4,Table1[Chapter],0)) -> Vector algebra | H4: {=IFERROR(INDEX('Pivot Chapters'!$B$5:$H$18,MATCH(Dashboard!$G4,'Pivot Chapters'!$A$5:$A$18,0),_xlfn.XMATCH(Dashboard!H$2,'Pivot Chapters'!$B$4:$H$4,0,1)),0)} -> 0 | I4: {=IFERROR(INDEX('Pivot Chapters'!$B$5:$H$18,MATCH(Dashboard!$G4,'Pivot Chapters'!$A$5:$A$18,0),_xlfn.XMATCH(Dashboard!I$2,'Pivot Chapters'!$B$4:$H$4,0,1)),0)} -> 0 | J4: {=IFERROR(INDEX('Pivot Chapters'!$B$5:$H$18,MATCH(Dashboard!$G4,'Pivot Chapters'!$A$5:$A$18,0),_xlfn.XMATCH(Dashboard!J$2,'Pivot Chapters'!$B$4:$H$4,0,1)),0)} -> 0 | K4: {=IFERROR(INDEX('Pivot Chapters'!$B$5:$H$18,MATCH(Dashboard!$G4,'Pivot Chapters'!$A$5:$A$18,0),_xlfn.XMATCH(Dashboard!K$2,'Pivot Chapters'!$B$4:$H$4,0,1)),0)} -> 0 | L4: {=IFERROR(INDEX('Pivot Chapters'!$B$5:$H$18,MATCH(Dashboard!$G4,'Pivot Chapters'!$A$5:$A$18,0),_xlfn.XMATCH(Dashboard!L$2,'Pivot Chapters'!$B$4:$H$4,0,1)),0)} -> 0 | M4: {=IFERROR(INDEX('Pivot Chapters'!$B$5:$H$18,MATCH(Dashboard!$G4,'Pivot Chapters'!$A$5:$A$18,0),_xlfn.XMATCH(Dashboard!M$2,'Pivot Chapters'!$B$4:$H$4,0,1)),0)} -> 5 | O4: B | P4: {=IFERROR(INDEX('Pivot Pilots'!$B$5:$H$7,MATCH($O4,'Pivot Pilots'!$A$5:$A$6,0),_xlfn.XMATCH(P$2,'Pivot Pilots'!$B$4:$H$4,0,1)),0)} -> 0 | Q4: {=IFERROR(INDEX('Pivot Pilots'!$B$5:$H$7,MATCH($O4,'Pivot Pilots'!$A$5:$A$6,0),_xlfn.XMATCH(Q$2,'Pivot Pilots'!$B$4:$H$4,0,1)),0)} -> 10 | R4: {=IFERROR(INDEX('Pivot Pilots'!$B$5:$H$7,MATCH($O4,'Pivot Pilots'!$A$5:$A$6,0),_xlfn.XMATCH(R$2,'Pivot Pilots'!$B$4:$H$4,0,1)),0)} -> 0 | S4: {=IFERROR(INDEX('Pivot Pilots'!$B$5:$H$7,MATCH($O4,'Pivot Pilots'!$A$5:$A$6,0),_xlfn.XMATCH(S$2,'Pivot Pilots'!$B$4:$H$4,0,1)),0)} -> 0 | T4: {=IFERROR(INDEX('Pivot Pilots'!$B$5:$H$7,MATCH($O4,'Pivot Pilots'!$A$5:$A$6,0),_xlfn.XMATCH(T$2,'Pivot Pilots'!$B$4:$H$4,0,1)),0)} -> 0 | U4: {=IFERROR(INDEX('Pivot Pilots'!$B$5:$H$7,MATCH($O4,'Pivot Pilots'!$A$5:$A$6,0),_xlfn.XMATCH(U$2,'Pivot Pilots'!$B$4:$H$4,0,1)),0)} -> 0
B5: Review 1 completed | C5: =COUNTIF(Table1[Review 1 completed],"Yes") -> 32 | D5: =C5/$C$3 -> 0.33333333 | F5: 3 | G5: =INDEX(Table1[Ch.Name],MATCH(Dashboard!$F5,Table1[Chapter],0)) -> Functions and curves | H5: {=IFERROR(INDEX('Pivot Chapters'!$B$5:$H$18,MATCH(Dashboard!$G5,'Pivot Chapters'!$A$5:$A$18,0),_xlfn.XMATCH(Dashboard!H$2,'Pivot Chapters'!$B$4:$H$4,0,1)),0)} -> 0 | I5: {=IFERROR(INDEX('Pivot Chapters'!$B$5:$H$18,MATCH(Dashboard!$G5,'Pivot Chapters'!$A$5:$A$18,0),_xlfn.XMATCH(Dashboard!I$2,'Pivot Chapters'!$B$4:$H$4,0,1)),0)} -> 0 | J5: {=IFERROR(INDEX('Pivot Chapters'!$B$5:$H$18,MATCH(Dashboard!$G5,'Pivot Chapters'!$A$5:$A$18,0),_xlfn.XMATCH(Dashboard!J$2,'Pivot Chapters'!$B$4:$H$4,0,1)),0)} -> 1 | K5: {=IFERROR(INDEX('Pivot Chapters'!$B$5:$H$18,MATCH(Dashboard!$G5,'Pivot Chapters'!$A$5:$A$18,0),_xlfn.XMATCH(Dashboard!K$2,'Pivot Chapters'!$B$4:$H$4,0,1)),0)} -> 6 | L5: {=IFERROR(INDEX('Pivot Chapters'!$B$5:$H$18,MATCH(Dashboard!$G5,'Pivot Chapters'!$A$5:$A$18,0),_xlfn.XMATCH(Dashboard!L$2,'Pivot Chapters'!$B$4:$H$4,0,1)),0)} -> 0 | M5: {=IFERROR(INDEX('Pivot Chapters'!$B$5:$H$18,MATCH(Dashboard!$G5,'Pivot Chapters'!$A$5:$A$18,0),_xlfn.XMATCH(Dashboard!M$2,'Pivot Chapters'!$B$4:$H$4,0,1)),0)} -> 1
B6: Ready for review 2 | C6: =COUNTIF(Table1[Ready for review 2],"Yes") -> 18 | D6: =C6/$C$3 -> 0.1875 | F6: 4 | G6: =INDEX(Table1[Ch.Name],MATCH(Dashboard!$F6,Table1[Chapter],0)) -> Differentiation | H6: {=IFERROR(INDEX('Pivot Chapters'!$B$5:$H$18,MATCH(Dashboard!$G6,'Pivot Chapters'!$A$5:$A$18,0),_xlfn.XMATCH(Dashboard!H$2,'Pivot Chapters'!$B$4:$H$4,0,1)),0)} -> 0 | I6: {=IFERROR(INDEX('Pivot Chapters'!$B$5:$H$18,MATCH(Dashboard!$G6,'Pivot Chapters'!$A$5:$A$18,0),_xlfn.XMATCH(Dashboard!I$2,'Pivot Chapters'!$B$4:$H$4,0,1)),0)} -> 1 | J6: {=IFERROR(INDEX('Pivot Chapters'!$B$5:$H$18,MATCH(Dashboard!$G6,'Pivot Chapters'!$A$5:$A$18,0),_xlfn.XMATCH(Dashboard!J$2,'Pivot Chapters'!$B$4:$H$4,0,1)),0)} -> 3 | K6: {=IFERROR(INDEX('Pivot Chapters'!$B$5:$H$18,MATCH(Dashboard!$G6,'Pivot Chapters'!$A$5:$A$18,0),_xlfn.XMATCH(Dashboard!K$2,'Pivot Chapters'!$B$4:$H$4,0,1)),0)} -> 4 | L6: {=IFERROR(INDEX('Pivot Chapters'!$B$5:$H$18,MATCH(Dashboard!$G6,'Pivot Chapters'!$A$5:$A$18,0),_xlfn.XMATCH(Dashboard!L$2,'Pivot Chapters'!$B$4:$H$4,0,1)),0)} -> 0 | M6: {=IFERROR(INDEX('Pivot Chapters'!$B$5:$H$18,MATCH(Dashboard!$G6,'Pivot Chapters'!$A$5:$A$18,0),_xlfn.XMATCH(Dashboard!M$2,'Pivot Chapters'!$B$4:$H$4,0,1)),0)} -> 0
B7: Review 2 completed | C7: =COUNTIF(Table1[Review 2 completed],"Yes") -> 6 | D7: =C7/$C$3 -> 0.0625 | F7: 5 | G7: =INDEX(Table1[Ch.Name],MATCH(Dashboard!$F7,Table1[Chapter],0)) -> Integration | H7: {=IFERROR(INDEX('Pivot Chapters'!$B$5:$H$18,MATCH(Dashboard!$G7,'Pivot Chapters'!$A$5:$A$18,0),_xlfn.XMATCH(Dashboard!H$2,'Pivot Chapters'!$B$4:$H$4,0,1)),0)} -> 0 | I7: {=IFERROR(INDEX('Pivot Chapters'!$B$5:$H$18,MATCH(Dashboard!$G7,'Pivot Chapters'!$A$5:$A$18,0),_xlfn.XMATCH(Dashboard!I$2,'Pivot Chapters'!$B$4:$H$4,0,1)),0)} -> 3 | J7: {=IFERROR(INDEX('Pivot Chapters'!$B$5:$H$18,MATCH(Dashboard!$G7,'Pivot Chapters'!$A$5:$A$18,0),_xlfn.XMATCH(Dashboard!J$2,'Pivot Chapters'!$B$4:$H$4,0,1)),0)} -> 4 | K7: {=IFERROR(INDEX('Pivot Chapters'!$B$5:$H$18,MATCH(Dashboard!$G7,'Pivot Chapters'!$A$5:$A$18,0),_xlfn.XMATCH(Dashboard!K$2,'Pivot Chapters'!$B$4:$H$4,0,1)),0)} -> 2 | L7: {=IFERROR(INDEX('Pivot Chapters'!$B$5:$H$18,MATCH(Dashboard!$G7,'Pivot Chapters'!$A$5:$A$18,0),_xlfn.XMATCH(Dashboard!L$2,'Pivot Chapters'!$B$4:$H$4,0,1)),0)} -> 0 | M7: {=IFERROR(INDEX('Pivot Chapters'!$B$5:$H$18,MATCH(Dashboard!$G7,'Pivot Chapters'!$A$5:$A$18,0),_xlfn.XMATCH(Dashboard!M$2,'Pivot Chapters'!$B$4:$H$4,0,1)),0)} -> 0
B8: Finished sections | C8: =COUNTIF(Table1[Finished],"Yes") -> 6 | D8: =C8/$C$3 -> 0.0625 | F8: 6 | G8: =INDEX(Table1[Ch.Name],MATCH(Dashboard!$F8,Table1[Chapter],0)) -> Sequences | H8: {=IFERROR(INDEX('Pivot Chapters'!$B$5:$H$18,MATCH(Dashboard!$G8,'Pivot Chapters'!$A$5:$A$18,0),_xlfn.XMATCH(Dashboard!H$2,'Pivot Chapters'!$B$4:$H$4,0,1)),0)} -> 0 | I8: {=IFERROR(INDEX('Pivot Chapters'!$B$5:$H$18,MATCH(Dashboard!$G8,'Pivot Chapters'!$A$5:$A$18,0),_xlfn.XMATCH(Dashboard!I$2,'Pivot Chapters'!$B$4:$H$4,0,1)),0)} -> 3 | J8: {=IFERROR(INDEX('Pivot Chapters'!$B$5:$H$18,MATCH(Dashboard!$G8,'Pivot Chapters'!$A$5:$A$18,0),_xlfn.XMATCH(Dashboard!J$2,'Pivot Chapters'!$B$4:$H$4,0,1)),0)} -> 0 | K8: {=IFERROR(INDEX('Pivot Chapters'!$B$5:$H$18,MATCH(Dashboard!$G8,'Pivot Chapters'!$A$5:$A$18,0),_xlfn.XMATCH(Dashboard!K$2,'Pivot Chapters'!$B$4:$H$4,0,1)),0)} -> 0 | L8: {=IFERROR(INDEX('Pivot Chapters'!$B$5:$H$18,MATCH(Dashboard!$G8,'Pivot Chapters'!$A$5:$A$18,0),_xlfn.XMATCH(Dashboard!L$2,'Pivot Chapters'!$B$4:$H$4,0,1)),0)} -> 0 | M8: {=IFERROR(INDEX('Pivot Chapters'!$B$5:$H$18,MATCH(Dashboard!$G8,'Pivot Chapters'!$A$5:$A$18,0),_xlfn.XMATCH(Dashboard!M$2,'Pivot Chapters'!$B$4:$H$4,0,1)),0)} -> 0
F9: 7 | G9: =INDEX(Table1[Ch.Name],MATCH(Dashboard!$F9,Table1[Chapter],0)) -> Series | H9: {=IFERROR(INDEX('Pivot Chapters'!$B$5:$H$18,MATCH(Dashboard!$G9,'Pivot Chapters'!$A$5:$A$18,0),_xlfn.XMATCH(Dashboard!H$2,'Pivot Chapters'!$B$4:$H$4,0,1)),0)} -> 0 | I9: {=IFERROR(INDEX('Pivot Chapters'!$B$5:$H$18,MATCH(Dashboard!$G9,'Pivot Chapters'!$A$5:$A$18,0),_xlfn.XMATCH(Dashboard!I$2,'Pivot Chapters'!$B$4:$H$4,0,1)),0)} -> 11 | J9: {=IFERROR(INDEX('Pivot Chapters'!$B$5:$H$18,MATCH(Dashboard!$G9,'Pivot Chapters'!$A$5:$A$18,0),_xlfn.XMATCH(Dashboard!J$2,'Pivot Chapters'!$B$4:$H$4,0,1)),0)} -> 0 | K9: {=IFERROR(INDEX('Pivot Chapters'!$B$5:$H$18,MATCH(Dashboard!$G9,'Pivot Chapters'!$A$5:$A$18,0),_xlfn.XMATCH(Dashboard!K$2,'Pivot Chapters'!$B$4:$H$4,0,1)),0)} -> 0 | L9: {=IFERROR(INDEX('Pivot Chapters'!$B$5:$H$18,MATCH(Dashboard!$G9,'Pivot Chapters'!$A$5:$A$18,0),_xlfn.XMATCH(Dashboard!L$2,'Pivot Chapters'!$B$4:$H$4,0,1)),0)} -> 0 | M9: {=IFERROR(INDEX('Pivot Chapters'!$B$5:$H$18,MATCH(Dashboard!$G9,'Pivot Chapters'!$A$5:$A$18,0),_xlfn.XMATCH(Dashboard!M$2,'Pivot Chapters'!$B$4:$H$4,0,1)),0)} -> 0
F10: 8 | G10: =INDEX(Table1[Ch.Name],MATCH(Dashboard!$F10,Table1[Chapter],0)) -> Functions, curves and surfaces | H10: {=IFERROR(INDEX('Pivot Chapters'!$B$5:$H$18,MATCH(Dashboard!$G10,'Pivot Chapters'!$A$5:$A$18,0),_xlfn.XMATCH(Dashboard!H$2,'Pivot Chapters'!$B$4:$H$4,0,1)),0)} -> 0 | I10: {=IFERROR(INDEX('Pivot Chapters'!$B$5:$H$18,MATCH(Dashboard!$G10,'Pivot Chapters'!$A$5:$A$18,0),_xlfn.XMATCH(Dashboard!I$2,'Pivot Chapters'!$B$4:$H$4,0,1)),0)} -> 0 | J10: {=IFERROR(INDEX('Pivot Chapters'!$B$5:$H$18,MATCH(Dashboard!$G10,'Pivot Chapters'!$A$5:$A$18,0),_xlfn.XMATCH(Dashboard!J$2,'Pivot Chapters'!$B$4:$H$4,0,1)),0)} -> 0 | K10: {=IFERROR(INDEX('Pivot Chapters'!$B$5:$H$18,MATCH(Dashboard!$G10,'Pivot Chapters'!$A$5:$A$18,0),_xlfn.XMATCH(Dashboard!K$2,'Pivot Chapters'!$B$4:$H$4,0,1)),0)} -> 0 | L10: {=IFERROR(INDEX('Pivot Chapters'!$B$5:$H$18,MATCH(Dashboard!$G10,'Pivot Chapters'!$A$5:$A$18,0),_xlfn.XMATCH(Dashboard!L$2,'Pivot Chapters'!$B$4:$H$4,0,1)),0)} -> 0 | M10: {=IFERROR(INDEX('Pivot Chapters'!$B$5:$H$18,MATCH(Dashboard!$G10,'Pivot Chapters'!$A$5:$A$18,0),_xlfn.XMATCH(Dashboard!M$2,'Pivot Chapters'!$B$4:$H$4,0,1)),0)} -> 0
F11: 9 | G11: =INDEX(Table1[Ch.Name],MATCH(Dashboard!$F11,Table1[Chapter],0)) -> Partial differentiation | H11: {=IFERROR(INDEX('Pivot Chapters'!$B$5:$H$18,MATCH(Dashboard!$G11,'Pivot Chapters'!$A$5:$A$18,0),_xlfn.XMATCH(Dashboard!H$2,'Pivot Chapters'!$B$4:$H$4,0,1)),0)} -> 0 | I11: {=IFERROR(INDEX('Pivot Chapters'!$B$5:$H$18,MATCH(Dashboard!$G11,'Pivot Chapters'!$A$5:$A$18,0),_xlfn.XMATCH(Dashboard!I$2,'Pivot Chapters'!$B$4:$H$4,0,1)),0)} -> 0 | J11: {=IFERROR(INDEX('Pivot Chapters'!$B$5:$H$18,MATCH(Dashboard!$G11,'Pivot Chapters'!$A$5:$A$18,0),_xlfn.XMATCH(Dashboard!J$2,'Pivot Chapters'!$B$4:$H$4,0,1)),0)} -> 0 | K11: {=IFERROR(INDEX('Pivot Chapters'!$B$5:$H$18,MATCH(Dashboard!$G11,'Pivot Chapters'!$A$5:$A$18,0),_xlfn.XMATCH(Dashboard!K$2,'Pivot Chapters'!$B$4:$H$4,0,1)),0)} -> 0 | L11: {=IFERROR(INDEX('Pivot Chapters'!$B$5:$H$18,MATCH(Dashboard!$G11,'Pivot Chapters'!$A$5:$A$18,0),_xlfn.XMATCH(Dashboard!L$2,'Pivot Chapters'!$B$4:$H$4,0,1)),0)} -> 0 | M11: {=IFERROR(INDEX('Pivot Chapters'!$B$5:$H$18,MATCH(Dashboard!$G11,'Pivot Chapters'!$A$5:$A$18,0),_xlfn.XMATCH(Dashboard!M$2,'Pivot Chapters'!$B$4:$H$4,0,1)),0)} -> 0
F12: 10 | G12: =INDEX(Table1[Ch.Name],MATCH(Dashboard!$F12,Table1[Chapter],0)) -> Multivariable integration | H12: {=IFERROR(INDEX('Pivot Chapters'!$B$5:$H$18,MATCH(Dashboard!$G12,'Pivot Chapters'!$A$5:$A$18,0),_xlfn.XMATCH(Dashboard!H$2,'Pivot Chapters'!$B$4:$H$4,0,1)),0)} -> 0 | I12: {=IFERROR(INDEX('Pivot Chapters'!$B$5:$H$18,MATCH(Dashboard!$G12,'Pivot Chapters'!$A$5:$A$18,0),_xlfn.XMATCH(Dashboard!I$2,'Pivot Chapters'!$B$4:$H$4,0,1)),0)} -> 0 | J12: {=IFERROR(INDEX('Pivot Chapters'!$B$5:$H$18,MATCH(Dashboard!$G12,'Pivot Chapters'!$A$5:$A$18,0),_xlfn.XMATCH(Dashboard!J$2,'Pivot Chapters'!$B$4:$H$4,0,1)),0)} -> 0 | K12: {=IFERROR(INDEX('Pivot Chapters'!$B$5:$H$18,MATCH(Dashboard!$G12,'Pivot Chapters'!$A$5:$A$18,0),_xlfn.XMATCH(Dashboard!K$2,'Pivot Chapters'!$B$4:$H$4,0,1)),0)} -> 0 | L12: {=IFERROR(INDEX('Pivot Chapters'!$B$5:$H$18,MATCH(Dashboard!$G12,'Pivot Chapters'!$A$5:$A$18,0),_xlfn.XMATCH(Dashboard!L$2,'Pivot Chapters'!$B$4:$H$4,0,1)),0)} -> 0 | M12: {=IFERROR(INDEX('Pivot Chapters'!$B$5:$H$18,MATCH(Dashboard!$G12,'Pivot Chapters'!$A$5:$A$18,0),_xlfn.XMATCH(Dashboard!M$2,'Pivot Chapters'!$B$4:$H$4,0,1)),0)} -> 0
F13: 11 | G13: =INDEX(Table1[Ch.Name],MATCH(Dashboard!$F13,Table1[Chapter],0)) -> Vector calculus | H13: {=IFERROR(INDEX('Pivot Chapters'!$B$5:$H$18,MATCH(Dashboard!$G13,'Pivot Chapters'!$A$5:$A$18,0),_xlfn.XMATCH(Dashboard!H$2,'Pivot Chapters'!$B$4:$H$4,0,1)),0)} -> 0 | I13: {=IFERROR(INDEX('Pivot Chapters'!$B$5:$H$18,MATCH(Dashboard!$G13,'Pivot Chapters'!$A$5:$A$18,0),_xlfn.XMATCH(Dashboard!I$2,'Pivot Chapters'!$B$4:$H$4,0,1)),0)} -> 0 | J13: {=IFERROR(INDEX('Pivot Chapters'!$B$5:$H$18,MATCH(Dashboard!$G13,'Pivot Chapters'!$A$5:$A$18,0),_xlfn.XMATCH(Dashboard!J$2,'Pivot Chapters'!$B$4:$H$4,0,1)),0)} -> 0 | K13: {=IFERROR(INDEX('Pivot Chapters'!$B$5:$H$18,MATCH(Dashboard!$G13,'Pivot Chapters'!$A$5:$A$18,0),_xlfn.XMATCH(Dashboard!K$2,'Pivot Chapters'!$B$4:$H$4,0,1)),0)} -> 0 | L13: {=IFERROR(INDEX('Pivot Chapters'!$B$5:$H$18,MATCH(Dashboard!$G13,'Pivot Chapters'!$A$5:$A$18,0),_xlfn.XMATCH(Dashboard!L$2,'Pivot Chapters'!$B$4:$H$4,0,1)),0)} -> 0 | M13: {=IFERROR(INDEX('Pivot Chapters'!$B$5:$H$18,MATCH(Dashboard!$G13,'Pivot Chapters'!$A$5:$A$18,0),_xlfn.XMATCH(Dashboard!M$2,'Pivot Chapters'!$B$4:$H$4,0,1)),0)} -> 0
F14: 12 | G14: =INDEX(Table1[Ch.Name],MATCH(Dashboard!$F14,Table1[Chapter],0)) -> Introduction to differential equations | H14: {=IFERROR(INDEX('Pivot Chapters'!$B$5:$H$18,MATCH(Dashboard!$G14,'Pivot Chapters'!$A$5:$A$18,0),_xlfn.XMATCH(Dashboard!H$2,'Pivot Chapters'!$B$4:$H$4,0,1)),0)} -> 0 | I14: {=IFERROR(INDEX('Pivot Chapters'!$B$5:$H$18,MATCH(Dashboard!$G14,'Pivot Chapters'!$A$5:$A$18,0),_xlfn.XMATCH(Dashboard!I$2,'Pivot Chapters'!$B$4:$H$4,0,1)),0)} -> 0 | J14: {=IFERROR(INDEX('Pivot Chapters'!$B$5:$H$18,MATCH(Dashboard!$G14,'Pivot Chapters'!$A$5:$A$18,0),_xlfn.XMATCH(Dashboard!J$2,'Pivot Chapters'!$B$4:$H$4,0,1)),0)} -> 1 | K14: {=IFERROR(INDEX('Pivot Chapters'!$B$5:$H$18,MATCH(Dashboard!$G14,'Pivot Chapters'!$A$5:$A$18,0),_xlfn.XMATCH(Dashboard!K$2,'Pivot Chapters'!$B$4:$H$4,0,1)),0)} -> 0 | L14: {=IFERROR(INDEX('Pivot Chapters'!$B$5:$H$18,MATCH(Dashboard!$G14,'Pivot Chapters'!$A$5:$A$18,0),_xlfn.XMATCH(Dashboard!L$2,'Pivot Chapters'!$B$4:$H$4,0,1)),0)} -> 0 | M14: {=IFERROR(INDEX('Pivot Chapters'!$B$5:$H$18,MATCH(Dashboard!$G14,'Pivot Chapters'!$A$5:$A$18,0),_xlfn.XMATCH(Dashboard!M$2,'Pivot Chapters'!$B$4:$H$4,0,1)),0)} -> 0
F15: 13 | G15: =INDEX(Table1[Ch.Name],MATCH(Dashboard!$F15,Table1[Chapter],0)) -> First-order ordinary differential equations | H15: {=IFERROR(INDEX('Pivot Chapters'!$B$5:$H$18,MATCH(Dashboard!$G15,'Pivot Chapters'!$A$5:$A$18,0),_xlfn.XMATCH(Dashboard!H$2,'Pivot Chapters'!$B$4:$H$4,0,1)),0)} -> 0 | I15: {=IFERROR(INDEX('Pivot Chapters'!$B$5:$H$18,MATCH(Dashboard!$G15,'Pivot Chapters'!$A$5:$A$18,0),_xlfn.XMATCH(Dashboard!I$2,'Pivot Chapters'!$B$4:$H$4,0,1)),0)} -> 1 | J15: {=IFERROR(INDEX('Pivot Chapters'!$B$5:$H$18,MATCH(Dashboard!$G15,'Pivot Chapters'!$A$5:$A$18,0),_xlfn.XMATCH(Dashboard!J$2,'Pivot Chapters'!$B$4:$H$4,0,1)),0)} -> 1 | K15: {=IFERROR(INDEX('Pivot Chapters'!$B$5:$H$18,MATCH(Dashboard!$G15,'Pivot Chapters'!$A$5:$A$18,0),_xlfn.XMATCH(Dashboard!K$2,'Pivot Chapters'!$B$4:$H$4,0,1)),0)} -> 0 | L15: {=IFERROR(INDEX('Pivot Chapters'!$B$5:$H$18,MATCH(Dashboard!$G15,'Pivot Chapters'!$A$5:$A$18,0),_xlfn.XMATCH(Dashboard!L$2,'Pivot Chapters'!$B$4:$H$4,0,1)),0)} -> 0 | M15: {=IFERROR(INDEX('Pivot Chapters'!$B$5:$H$18,MATCH(Dashboard!$G15,'Pivot Chapters'!$A$5:$A$18,0),_xlfn.XMATCH(Dashboard!M$2,'Pivot Chapters'!$B$4:$H$4,0,1)),0)} -> 0
F16: 14 | G16: =INDEX(Table1[Ch.Name],MATCH(Dashboard!$F16,Table1[Chapter],0)) -> Second-order linear ordinary differential equations | H16: {=IFERROR(INDEX('Pivot Chapters'!$B$5:$H$18,MATCH(Dashboard!$G16,'Pivot Chapters'!$A$5:$A$18,0),_xlfn.XMATCH(Dashboard!H$2,'Pivot Chapters'!$B$4:$H$4,0,1)),0)} -> 0 | I16: {=IFERROR(INDEX('Pivot Chapters'!$B$5:$H$18,MATCH(Dashboard!$G16,'Pivot Chapters'!$A$5:$A$18,0),_xlfn.XMATCH(Dashboard!I$2,'Pivot Chapters'!$B$4:$H$4,0,1)),0)} -> 0 | J16: {=IFERROR(INDEX('Pivot Chapters'!$B$5:$H$18,MATCH(Dashboard!$G16,'Pivot Chapters'!$A$5:$A$18,0),_xlfn.XMATCH(Dashboard!J$2,'Pivot Chapters'!$B$4:$H$4,0,1)),0)} -> 1 | K16: {=IFERROR(INDEX('Pivot Chapters'!$B$5:$H$18,MATCH(Dashboard!$G16,'Pivot Chapters'!$A$5:$A$18,0),_xlfn.XMATCH(Dashboard!K$2,'Pivot Chapters'!$B$4:$H$4,0,1)),0)} -> 0 | L16: {=IFERROR(INDEX('Pivot Chapters'!$B$5:$H$18,MATCH(Dashboard!$G16,'Pivot Chapters'!$A$5:$A$18,0),_xlfn.XMATCH(Dashboard!L$2,'Pivot Chapters'!$B$4:$H$4,0,1)),0)} -> 0 | M16: {=IFERROR(INDEX('Pivot Chapters'!$B$5:$H$18,MATCH(Dashboard!$G16,'Pivot Chapters'!$A$5:$A$18,0),_xlfn.XMATCH(Dashboard!M$2,'Pivot Chapters'!$B$4:$H$4,0,1)),0)} -> 0

Sheet Pivot Chapters
A3: Count of Stage | B3: Column Labels
A4: Row Labels | B4: Finished | C4: In early stages | D4: Ready for review 1 | E4: Ready for review 2 | F4: Review 1 completed | G4: Review 2 completed | H4: Not started | I4: Early stages | J4: Grand Total
A5: Differentiation | D5: 1 | E5: 4 | F5: 3 | I5: 1 | J5: 9
A6: First-order ordinary differential equations | D6: 1 | F6: 1 | I6: 5 | J6: 7
A7: Functions and curves | B7: 1 | E7: 6 | F7: 1 | H7: 1 | J7: 9
A8: Functions, curves and surfaces | H8: 7 | J8: 7
A9: Integration | D9: 3 | E9: 2 | F9: 4 | J9: 9
A10: Introduction to differential equations | F10: 1 | I10: 1 | J10: 2
A11: Multivariable integration | H11: 3 | I11: 4 | J11: 7
A12: Numbers and coordinate systems | D12: 1 | F12: 3 | H12: 1 | I12: 2 | J12: 7
A13: Partial differentiation | H13: 6 | J13: 6
A14: Second-order linear ordinary differential equations | F14: 1 | H14: 2 | I14: 2 | J14: 5
A15: Sequences | D15: 3 | H15: 1 | J15: 4
A16: Series | D16: 11 | J16: 11
A17: Vector algebra | B17: 5 | J17: 5
A18: Vector calculus | H18: 8 | J18: 8
A19: Grand Total | B19: 6 | D19: 20 | E19: 12 | F19: 14 | H19: 29 | I19: 15 | J19: 96

Sheet Pivot Pilots
A3: Count of Stage | B3: Column Labels
A4: Row Labels | B4: Finished | C4: Ready for review 1 | D4: Ready for review 2 | E4: Review 1 completed | F4: Not started | G4: Early stages | H4: Grand Total
A5: A | B5: 1 | D5: 12 | E5: 10 | H5: 23
A6: B | C6: 10 | H6: 10
A7: (blank) | B7: 5 | C7: 10 | E7: 4 | F7: 29 | G7: 15 | H7: 63
A8: Grand Total | B8: 6 | C8: 20 | D8: 12 | E8: 14 | F8: 29 | G8: 15 | H8: 96

Sheet Details
A1: Chapter | B1: Ch.Name | C1: Section | D1: Sec.Name | E1: Author | F1: Early stages | G1: Ready for review 1 | H1: Review 1 completed | I1: Ready for review 2 | J1: Review 2 completed | K1: Part of pilot | L1: Finished | M1: Stage
A2: 1 | B2: Numbers and coordinate systems | C2: 1 | D2: Set theory and logic | M2: =IF(Table1[[#This Row],[Finished]]="Yes",Table1[[#Headers],[Finished]],IF(Table1[[#This Row],[Review 2 completed]]="Yes",Table1[[#Headers],[Review 2 completed]],IF(Table1[[#This Row],[Ready for review 2]]="Yes",Table1[[#Headers],[Ready for review 2]],IF(Table1[[#This Row],[Review 1 completed]]="Yes",Table1[[#Headers],[Review 1 completed]],IF(Table1[[#This Row],[Ready for review 1]]="Yes",Table1[[#Headers],[Ready for review 1]],IF(Table1[[#This Row],[Early stages]]="Yes",Table1[[#Headers],[Early stages]],"Not started")))))) -> Not started
A3: 1 | B3: Numbers and coordinate systems | C3: 2 | D3: Real numbers | E3: W.M. Schouten-Straatman | F3: Yes | M3: =IF(Table1[[#This Row],[Finished]]="Yes",Table1[[#Headers],[Finished]],IF(Table1[[#This Row],[Review 2 completed]]="Yes",Table1[[#Headers],[Review 2 completed]],IF(Table1[[#This Row],[Ready for review 2]]="Yes",Table1[[#Headers],[Ready for review 2]],IF(Table1[[#This Row],[Review 1 completed]]="Yes",Table1[[#Headers],[Review 1 completed]],IF(Table1[[#This Row],[Ready for review 1]]="Yes",Table1[[#Headers],[Ready for review 1]],IF(Table1[[#This Row],[Early stages]]="Yes",Table1[[#Headers],[Early stages]],"Not started")))))) -> Early stages
A4: 1 | B4: Numbers and coordinate systems | C4: 3 | D4: Complex numbers | E4: W.M. Schouten-Straatman | F4: Yes | G4: Yes | H4: Yes | K4: A | M4: =IF(Table1[[#This Row],[Finished]]="Yes",Table1[[#Headers],[Finished]],IF(Table1[[#This Row],[Review 2 completed]]="Yes",Table1[[#Headers],[Review 2 completed]],IF(Table1[[#This Row],[Ready for review 2]]="Yes",Table1[[#Headers],[Ready for review 2]],IF(Table1[[#This Row],[Review 1 completed]]="Yes",Table1[[#Headers],[Review 1 completed]],IF(Table1[[#This Row],[Ready for review 1]]="Yes",Table1[[#Headers],[Ready for review 1]],IF(Table1[[#This Row],[Early stages]]="Yes",Table1[[#Headers],[Early stages]],"Not started")))))) -> Review 1 completed
A5: 1 | B5: Numbers and coordinate systems | C5: 4 | D5: Trigonometry | E5: R. Koekoek | F5: Yes | G5: Yes | H5: Yes | M5: =IF(Table1[[#This Row],[Finished]]="Yes",Table1[[#Headers],[Finished]],IF(Table1[[#This Row],[Review 2 completed]]="Yes",Table1[[#Headers],[Review 2 completed]],IF(Table1[[#This Row],[Ready for review 2]]="Yes",Table1[[#Headers],[Ready for review 2]],IF(Table1[[#This Row],[Review 1 completed]]="Yes",Table1[[#Headers],[Review 1 completed]],IF(Table1[[#This Row],[Ready for review 1]]="Yes",Table1[[#Headers],[Ready for review 1]],IF(Table1[[#This Row],[Early stages]]="Yes",Table1[[#Headers],[Early stages]],"Not started")))))) -> Review 1 completed
A6: 1 | B6: Numbers and coordinate systems | C6: 5 | D6: Coordinate systems | E6: R. Koekoek | F6: Yes | M6: =IF(Table1[[#This Row],[Finished]]="Yes",Table1[[#Headers],[Finished]],IF(Table1[[#This Row],[Review 2 completed]]="Yes",Table1[[#Headers],[Review 2 completed]],IF(Table1[[#This Row],[Ready for review 2]]="Yes",Table1[[#Headers],[Ready for review 2]],IF(Table1[[#This Row],[Review 1 completed]]="Yes",Table1[[#Headers],[Review 1 completed]],IF(Table1[[#This Row],[Ready for review 1]]="Yes",Table1[[#Headers],[Ready for review 1]],IF(Table1[[#This Row],[Early stages]]="Yes",Table1[[#Headers],[Early stages]],"Not started")))))) -> Early stages
A7: 1 | B7: Numbers and coordinate systems | C7: 6 | D7: Polar form of complex numbers | E7: W.M. Schouten-Straatman | F7: Yes | G7: Yes | H7: Yes | K7: A | M7: =IF(Table1[[#This Row],[Finished]]="Yes",Table1[[#Headers],[Finished]],IF(Table1[[#This Row],[Review 2 completed]]="Yes",Table1[[#Headers],[Review 2 completed]],IF(Table1[[#This Row],[Ready for review 2]]="Yes",Table1[[#Headers],[Ready for review 2]],IF(Table1[[#This Row],[Review 1 completed]]="Yes",Table1[[#Headers],[Review 1 completed]],IF(Table1[[#This Row],[Ready for review 1]]="Yes",Table1[[#Headers],[Ready for review 1]],IF(Table1[[#This Row],[Early stages]]="Yes",Table1[[#Headers],[Early stages]],"Not started")))))) -> Review 1 completed
A8: 1 | B8: Numbers and coordinate systems | C8: 7 | D8: Finite summations and multiplications | E8: R. Koekoek | F8: Yes | G8: Yes | M8: =IF(Table1[[#This Row],[Finished]]="Yes",Table1[[#Headers],[Finished]],IF(Table1[[#This Row],[Review 2 completed]]="Yes",Table1[[#Headers],[Review 2 completed]],IF(Table1[[#This Row],[Ready for review 2]]="Yes",Table1[[#Headers],[Ready for review 2]],IF(Table1[[#This Row],[Review 1 completed]]="Yes",Table1[[#Headers],[Review 1 completed]],IF(Table1[[#This Row],[Ready for review 1]]="Yes",Table1[[#Headers],[Ready for review 1]],IF(Table1[[#This Row],[Early stages]]="Yes",Table1[[#Headers],[Early stages]],"Not started")))))) -> Ready for review 1
A9: 2 | B9: Vector algebra | C9: 1 | D9: Vectors | E9: A.T. Hensbergen & N.D. Verhulst | F9: Yes | G9: Yes | H9: Yes | I9: Yes | J9: Yes | L9: Yes | M9: =IF(Table1[[#This Row],[Finished]]="Yes",Table1[[#Headers],[Finished]],IF(Table1[[#This Row],[Review 2 completed]]="Yes",Table1[[#Headers],[Review 2 completed]],IF(Table1[[#This Row],[Ready for review 2]]="Yes",Table1[[#Headers],[Ready for review 2]],IF(Table1[[#This Row],[Review 1 completed]]="Yes",Table1[[#Headers],[Review 1 completed]],IF(Table1[[#This Row],[Ready for review 1]]="Yes",Table1[[#Headers],[Ready for review 1]],IF(Table1[[#This Row],[Early stages]]="Yes",Table1[[#Headers],[Early stages]],"Not started")))))) -> Finished
A10: 2 | B10: Vector algebra | C10: 2 | D10: Dot product | E10: A.T. Hensbergen & N.D. Verhulst | F10: Yes | G10: Yes | H10: Yes | I10: Yes | J10: Yes | L10: Yes | M10: =IF(Table1[[#This Row],[Finished]]="Yes",Table1[[#Headers],[Finished]],IF(Table1[[#This Row],[Review 2 completed]]="Yes",Table1[[#Headers],[Review 2 completed]],IF(Table1[[#This Row],[Ready for review 2]]="Yes",Table1[[#Headers],[Ready for review 2]],IF(Table1[[#This Row],[Review 1 completed]]="Yes",Table1[[#Headers],[Review 1 completed]],IF(Table1[[#This Row],[Ready for review 1]]="Yes",Table1[[#Headers],[Ready for review 1]],IF(Table1[[#This Row],[Early stages]]="Yes",Table1[[#Headers],[Early stages]],"Not started")))))) -> Finished
A11: 2 | B11: Vector algebra | C11: 3 | D11: Cross product | E11: A.T. Hensbergen & N.D. Verhulst | F11: Yes | G11: Yes | H11: Yes | I11: Yes | J11: Yes | L11: Yes | M11: =IF(Table1[[#This Row],[Finished]]="Yes",Table1[[#Headers],[Finished]],IF(Table1[[#This Row],[Review 2 completed]]="Yes",Table1[[#Headers],[Review 2 completed]],IF(Table1[[#This Row],[Ready for review 2]]="Yes",Table1[[#Headers],[Ready for review 2]],IF(Table1[[#This Row],[Review 1 completed]]="Yes",Table1[[#Headers],[Review 1 completed]],IF(Table1[[#This Row],[Ready for review 1]]="Yes",Table1[[#Headers],[Ready for review 1]],IF(Table1[[#This Row],[Early stages]]="Yes",Table1[[#Headers],[Early stages]],"Not started")))))) -> Finished
A12: 2 | B12: Vector algebra | C12: 4 | D12: Lines and planes | E12: A.T. Hensbergen & N.D. Verhulst | F12: Yes | G12: Yes | H12: Yes | I12: Yes | J12: Yes | L12: Yes | M12: =IF(Table1[[#This Row],[Finished]]="Yes",Table1[[#Headers],[Finished]],IF(Table1[[#This Row],[Review 2 completed]]="Yes",Table1[[#Headers],[Review 2 completed]],IF(Table1[[#This Row],[Ready for review 2]]="Yes",Table1[[#Headers],[Ready for review 2]],IF(Table1[[#This Row],[Review 1 completed]]="Yes",Table1[[#Headers],[Review 1 completed]],IF(Table1[[#This Row],[Ready for review 1]]="Yes",Table1[[#Headers],[Ready for review 1]],IF(Table1[[#This Row],[Early stages]]="Yes",Table1[[#Headers],[Early stages]],"Not started")))))) -> Finished
A13: 2 | B13: Vector algebra | C13: 5 | D13: Determinants | E13: A.T. Hensbergen & N.D. Verhulst | F13: Yes | G13: Yes | H13: Yes | I13: Yes | J13: Yes | L13: Yes | M13: =IF(Table1[[#This Row],[Finished]]="Yes",Table1[[#Headers],[Finished]],IF(Table1[[#This Row],[Review 2 completed]]="Yes",Table1[[#Headers],[Review 2 completed]],IF(Table1[[#This Row],[Ready for review 2]]="Yes",Table1[[#Headers],[Ready for review 2]],IF(Table1[[#This Row],[Review 1 completed]]="Yes",Table1[[#Headers],[Review 1 completed]],IF(Table1[[#This Row],[Ready for review 1]]="Yes",Table1[[#Headers],[Ready for review 1]],IF(Table1[[#This Row],[Early stages]]="Yes",Table1[[#Headers],[Early stages]],"Not started")))))) -> Finished
A14: 3 | B14: Functions and curves | C14: 1 | D14: Functions of one variable | E14: W.M. Schouten-Straatman | F14: Yes | G14: Yes | H14: Yes | I14: Yes | K14: A | M14: =IF(Table1[[#This Row],[Finished]]="Yes",Table1[[#Headers],[Finished]],IF(Table1[[#This Row],[Review 2 completed]]="Yes",Table1[[#Headers],[Review 2 completed]],IF(Table1[[#This Row],[Ready for review 2]]="Yes",Table1[[#Headers],[Ready for review 2]],IF(Table1[[#This Row],[Review 1 completed]]="Yes",Table1[[#Headers],[Review 1 completed]],IF(Table1[[#This Row],[Ready for review 1]]="Yes",Table1[[#Headers],[Ready for review 1]],IF(Table1[[#This Row],[Early stages]]="Yes",Table1[[#Headers],[Early stages]],"Not started")))))) -> Ready for review 2
A15: 3 | B15: Functions and curves | C15: 2 | D15: Properties of functions | E15: W.M. Schouten-Straatman | F15: Yes | G15: Yes | H15: Yes | I15: Yes | K15: A | M15: =IF(Table1[[#This Row],[Finished]]="Yes",Table1[[#Headers],[Finished]],IF(Table1[[#This Row],[Review 2 completed]]="Yes",Table1[[#Headers],[Review 2 completed]],IF(Table1[[#This Row],[Ready for review 2]]="Yes",Table1[[#Headers],[Ready for review 2]],IF(Table1[[#This Row],[Review 1 completed]]="Yes",Table1[[#Headers],[Review 1 completed]],IF(Table1[[#This Row],[Ready for review 1]]="Yes",Table1[[#Headers],[Ready for review 1]],IF(Table1[[#This Row],[Early stages]]="Yes",Table1[[#Headers],[Early stages]],"Not started")))))) -> Ready for review 2
A16: 3 | B16: Functions and curves | C16: 3 | D16: Curves in R^2 | E16: W.M. Schouten-Straatman | F16: Yes | G16: Yes | H16: Yes | M16: =IF(Table1[[#This Row],[Finished]]="Yes",Table1[[#Headers],[Finished]],IF(Table1[[#This Row],[Review 2 completed]]="Yes",Table1[[#Headers],[Review 2 completed]],IF(Table1[[#This Row],[Ready for review 2]]="Yes",Table1[[#Headers],[Ready for review 2]],IF(Table1[[#This Row],[Review 1 completed]]="Yes",Table1[[#Headers],[Review 1 completed]],IF(Table1[[#This Row],[Ready for review 1]]="Yes",Table1[[#Headers],[Ready for review 1]],IF(Table1[[#This Row],[Early stages]]="Yes",Table1[[#Headers],[Early stages]],"Not started")))))) -> Review 1 completed
A17: 3 | B17: Functions and curves | C17: 4 | D17: Rational functions | E17: D. den Ouden-van der Horst | F17: Yes | G17: Yes | H17: Yes | I17: Yes | J17: Yes | K17: A | L17: Yes | M17: =IF(Table1[[#This Row],[Finished]]="Yes",Table1[[#Headers],[Finished]],IF(Table1[[#This Row],[Review 2 completed]]="Yes",Table1[[#Headers],[Review 2 completed]],IF(Table1[[#This Row],[Ready for review 2]]="Yes",Table1[[#Headers],[Ready for review 2]],IF(Table1[[#This Row],[Review 1 completed]]="Yes",Table1[[#Headers],[Review 1 completed]],IF(Table1[[#This Row],[Ready for review 1]]="Yes",Table1[[#Headers],[Ready for review 1]],IF(Table1[[#This Row],[Early stages]]="Yes",Table1[[#Headers],[Early stages]],"Not started")))))) -> Finished
A18: 3 | B18: Functions and curves | C18: 5 | D18: Inverse functions | E18: W.M. Schouten-Straatman | F18: Yes | G18: Yes | H18: Yes | I18: Yes | K18: A | M18: =IF(Table1[[#This Row],[Finished]]="Yes",Table1[[#Headers],[Finished]],IF(Table1[[#This Row],[Review 2 completed]]="Yes",Table1[[#Headers],[Review 2 completed]],IF(Table1[[#This Row],[Ready for review 2]]="Yes",Table1[[#Headers],[Ready for review 2]],IF(Table1[[#This Row],[Review 1 completed]]="Yes",Table1[[#Headers],[Review 1 completed]],IF(Table1[[#This Row],[Ready for review 1]]="Yes",Table1[[#Headers],[Ready for review 1]],IF(Table1[[#This Row],[Early stages]]="Yes",Table1[[#Headers],[Early stages]],"Not started")))))) -> Ready for review 2
A19: 3 | B19: Functions and curves | C19: 6 | D19: Nonlinear equations of one variable | M19: =IF(Table1[[#This Row],[Finished]]="Yes",Table1[[#Headers],[Finished]],IF(Table1[[#This Row],[Review 2 completed]]="Yes",Table1[[#Headers],[Review 2 completed]],IF(Table1[[#This Row],[Ready for review 2]]="Yes",Table1[[#Headers],[Ready for review 2]],IF(Table1[[#This Row],[Review 1 completed]]="Yes",Table1[[#Headers],[Review 1 completed]],IF(Table1[[#This Row],[Ready for review 1]]="Yes",Table1[[#Headers],[Ready for review 1]],IF(Table1[[#This Row],[Early stages]]="Yes",Table1[[#Headers],[Early stages]],"Not started")))))) -> Not started
A20: 3 | B20: Functions and curves | C20: 7 | D20: Limits at a point | E20: W.M. Schouten-Straatman | F20: Yes | G20: Yes | H20: Yes | I20: Yes | K20: A | M20: =IF(Table1[[#This Row],[Finished]]="Yes",Table1[[#Headers],[Finished]],IF(Table1[[#This Row],[Review 2 completed]]="Yes",Table1[[#Headers],[Review 2 completed]],IF(Table1[[#This Row],[Ready for review 2]]="Yes",Table1[[#Headers],[Ready for review 2]],IF(Table1[[#This Row],[Review 1 completed]]="Yes",Table1[[#Headers],[Review 1 completed]],IF(Table1[[#This Row],[Ready for review 1]]="Yes",Table1[[#Headers],[Ready for review 1]],IF(Table1[[#This Row],[Early stages]]="Yes",Table1[[#Headers],[Early stages]],"Not started")))))) -> Ready for review 2
A21: 3 | B21: Functions and curves | C21: 8 | D21: Limits at infinity | E21: W.M. Schouten-Straatman | F21: Yes | G21: Yes | H21: Yes | I21: Yes | K21: A | M21: =IF(Table1[[#This Row],[Finished]]="Yes",Table1[[#Headers],[Finished]],IF(Table1[[#This Row],[Review 2 completed]]="Yes",Table1[[#Headers],[Review 2 completed]],IF(Table1[[#This Row],[Ready for review 2]]="Yes",Table1[[#Headers],[Ready for review 2]],IF(Table1[[#This Row],[Review 1 completed]]="Yes",Table1[[#Headers],[Review 1 completed]],IF(Table1[[#This Row],[Ready for review 1]]="Yes",Table1[[#Headers],[Ready for review 1]],IF(Table1[[#This Row],[Early stages]]="Yes",Table1[[#Headers],[Early stages]],"Not started")))))) -> Ready for review 2
A22: 3 | B22: Functions and curves | C22: 9 | D22: Continuity | E22: W.M. Schouten-Straatman | F22: Yes | G22: Yes | H22: Yes | I22: Yes | K22: A | M22: =IF(Table1[[#This Row],[Finished]]="Yes",Table1[[#Headers],[Finished]],IF(Table1[[#This Row],[Review 2 completed]]="Yes",Table1[[#Headers],[Review 2 completed]],IF(Table1[[#This Row],[Ready for review 2]]="Yes",Table1[[#Headers],[Ready for review 2]],IF(Table1[[#This Row],[Review 1 completed]]="Yes",Table1[[#Headers],[Review 1 completed]],IF(Table1[[#This Row],[Ready for review 1]]="Yes",Table1[[#Headers],[Ready for review 1]],IF(Table1[[#This Row],[Early stages]]="Yes",Table1[[#Headers],[Early stages]],"Not started")))))) -> Ready for review 2
A23: 4 | B23: Differentiation | C23: 1 | D23: Differentiability | E23: W.M. Schouten-Straatman | F23: Yes | G23: Yes | H23: Yes | K23: A | M23: =IF(Table1[[#This Row],[Finished]]="Yes",Table1[[#Headers],[Finished]],IF(Table1[[#This Row],[Review 2 completed]]="Yes",Table1[[#Headers],[Review 2 completed]],IF(Table1[[#This Row],[Ready for review 2]]="Yes",Table1[[#Headers],[Ready for review 2]],IF(Table1[[#This Row],[Review 1 completed]]="Yes",Table1[[#Headers],[Review 1 completed]],IF(Table1[[#This Row],[Ready for review 1]]="Yes",Table1[[#Headers],[Ready for review 1]],IF(Table1[[#This Row],[Early stages]]="Yes",Table1[[#Headers],[Early stages]],"Not started")))))) -> Review 1 completed
A24: 4 | B24: Differentiation | C24: 2 | D24: Chain rule | E24: W.M. Schouten-Straatman | F24: Yes | G24: Yes | H24: Yes | I24: Yes | K24: A | M24: =IF(Table1[[#This Row],[Finished]]="Yes",Table1[[#Headers],[Finished]],IF(Table1[[#This Row],[Review 2 completed]]="Yes",Table1[[#Headers],[Review 2 completed]],IF(Table1[[#This Row],[Ready for review 2]]="Yes",Table1[[#Headers],[Ready for review 2]],IF(Table1[[#This Row],[Review 1 completed]]="Yes",Table1[[#Headers],[Review 1 completed]],IF(Table1[[#This Row],[Ready for review 1]]="Yes",Table1[[#Headers],[Ready for review 1]],IF(Table1[[#This Row],[Early stages]]="Yes",Table1[[#Headers],[Early stages]],"Not started")))))) -> Ready for review 2
A25: 4 | B25: Differentiation | C25: 3 | D25: Product and quotient rule | E25: W.M. Schouten-Straatman | F25: Yes | G25: Yes | H25: Yes | I25: Yes | K25: A | M25: =IF(Table1[[#This Row],[Finished]]="Yes",Table1[[#Headers],[Finished]],IF(Table1[[#This Row],[Review 2 completed]]="Yes",Table1[[#Headers],[Review 2 completed]],IF(Table1[[#This Row],[Ready for review 2]]="Yes",Table1[[#Headers],[Ready for review 2]],IF(Table1[[#This Row],[Review 1 completed]]="Yes",Table1[[#Headers],[Review 1 completed]],IF(Table1[[#This Row],[Ready for review 1]]="Yes",Table1[[#Headers],[Ready for review 1]],IF(Table1[[#This Row],[Early stages]]="Yes",Table1[[#Headers],[Early stages]],"Not started")))))) -> Ready for review 2
A26: 4 | B26: Differentiation | C26: 4 | D26: Graphs and extreme values | E26: W.M. Schouten-Straatman | F26: Yes | G26: Yes | H26: Yes | I26: Yes | K26: A | M26: =IF(Table1[[#This Row],[Finished]]="Yes",Table1[[#Headers],[Finished]],IF(Table1[[#This Row],[Review 2 completed]]="Yes",Table1[[#Headers],[Review 2 completed]],IF(Table1[[#This Row],[Ready for review 2]]="Yes",Table1[[#Headers],[Ready for review 2]],IF(Table1[[#This Row],[Review 1 completed]]="Yes",Table1[[#Headers],[Review 1 completed]],IF(Table1[[#This Row],[Ready for review 1]]="Yes",Table1[[#Headers],[Ready for review 1]],IF(Table1[[#This Row],[Early stages]]="Yes",Table1[[#Headers],[Early stages]],"Not started")))))) -> Ready for review 2
A27: 4 | B27: Differentiation | C27: 5 | D27: Properties of graphs | E27: W.M. Schouten-Straatman | F27: Yes | M27: =IF(Table1[[#This Row],[Finished]]="Yes",Table1[[#Headers],[Finished]],IF(Table1[[#This Row],[Review 2 completed]]="Yes",Table1[[#Headers],[Review 2 completed]],IF(Table1[[#This Row],[Ready for review 2]]="Yes",Table1[[#Headers],[Ready for review 2]],IF(Table1[[#This Row],[Review 1 completed]]="Yes",Table1[[#Headers],[Review 1 completed]],IF(Table1[[#This Row],[Ready for review 1]]="Yes",Table1[[#Headers],[Ready for review 1]],IF(Table1[[#This Row],[Early stages]]="Yes",Table1[[#Headers],[Early stages]],"Not started")))))) -> Early stages
A28: 4 | B28: Differentiation | C28: 6 | D28: Slopes of curves in R^2 | E28: W.M. Schouten-Straatman | F28: Yes | G28: Yes | H28: Yes | K28: A | M28: =IF(Table1[[#This Row],[Finished]]="Yes",Table1[[#Headers],[Finished]],IF(Table1[[#This Row],[Review 2 completed]]="Yes",Table1[[#Headers],[Review 2 completed]],IF(Table1[[#This Row],[Ready for review 2]]="Yes",Table1[[#Headers],[Ready for review 2]],IF(Table1[[#This Row],[Review 1 completed]]="Yes",Table1[[#Headers],[Review 1 completed]],IF(Table1[[#This Row],[Ready for review 1]]="Yes",Table1[[#Headers],[Ready for review 1]],IF(Table1[[#This Row],[Early stages]]="Yes",Table1[[#Headers],[Early stages]],"Not started")))))) -> Review 1 completed
A29: 4 | B29: Differentiation | C29: 7 | D29: Derivatives of inverse functions | E29: W.M. Schouten-Straatman | F29: Yes | G29: Yes | H29: Yes | I29: Yes | K29: A | M29: =IF(Table1[[#This Row],[Finished]]="Yes",Table1[[#Headers],[Finished]],IF(Table1[[#This Row],[Review 2 completed]]="Yes",Table1[[#Headers],[Review 2 completed]],IF(Table1[[#This Row],[Ready for review 2]]="Yes",Table1[[#Headers],[Ready for review 2]],IF(Table1[[#This Row],[Review 1 completed]]="Yes",Table1[[#Headers],[Review 1 completed]],IF(Table1[[#This Row],[Ready for review 1]]="Yes",Table1[[#Headers],[Ready for review 1]],IF(Table1[[#This Row],[Early stages]]="Yes",Table1[[#Headers],[Early stages]],"Not started")))))) -> Ready for review 2
A30: 4 | B30: Differentiation | C30: 8 | D30: Approximating functions | E30: D. den Ouden-van der Horst | F30: Yes | G30: Yes | H30: Yes | M30: =IF(Table1[[#This Row],[Finished]]="Yes",Table1[[#Headers],[Finished]],IF(Table1[[#This Row],[Review 2 completed]]="Yes",Table1[[#Headers],[Review 2 completed]],IF(Table1[[#This Row],[Ready for review 2]]="Yes",Table1[[#Headers],[Ready for review 2]],IF(Table1[[#This Row],[Review 1 completed]]="Yes",Table1[[#Headers],[Review 1 completed]],IF(Table1[[#This Row],[Ready for review 1]]="Yes",Table1[[#Headers],[Ready for review 1]],IF(Table1[[#This Row],[Early stages]]="Yes",Table1[[#Headers],[Early stages]],"Not started")))))) -> Review 1 completed
A31: 4 | B31: Differentiation | C31: 9 | D31: l’Hospital’s rule | E31: W.M. Schouten-Straatman | F31: Yes | G31: Yes | M31: =IF(Table1[[#This Row],[Finished]]="Yes",Table1[[#Headers],[Finished]],IF(Table1[[#This Row],[Review 2 completed]]="Yes",Table1[[#Headers],[Review 2 completed]],IF(Table1[[#This Row],[Ready for review 2]]="Yes",Table1[[#Headers],[Ready for review 2]],IF(Table1[[#This Row],[Review 1 completed]]="Yes",Table1[[#Headers],[Review 1 completed]],IF(Table1[[#This Row],[Ready for review 1]]="Yes",Table1[[#Headers],[Ready for review 1]],IF(Table1[[#This Row],[Early stages]]="Yes",Table1[[#Headers],[Early stages]],"Not started")))))) -> Ready for review 1
A32: 5 | B32: Integration | C32: 1 | D32: Definite integrals | E32: R. Koekoek | F32: Yes | G32: Yes | H32: Yes | I32: Yes | K32: A | M32: =IF(Table1[[#This Row],[Finished]]="Yes",Table1[[#Headers],[Finished]],IF(Table1[[#This Row],[Review 2 completed]]="Yes",Table1[[#Headers],[Review 2 completed]],IF(Table1[[#This Row],[Ready for review 2]]="Yes",Table1[[#Headers],[Ready for review 2]],IF(Table1[[#This Row],[Review 1 completed]]="Yes",Table1[[#Headers],[Review 1 completed]],IF(Table1[[#This Row],[Ready for review 1]]="Yes",Table1[[#Headers],[Ready for review 1]],IF(Table1[[#This Row],[Early stages]]="Yes",Table1[[#Headers],[Early stages]],"Not started")))))) -> Ready for review 2
A33: 5 | B33: Integration | C33: 2 | D33: Indefinite integrals | E33: R. Koekoek | F33: Yes | G33: Yes | H33: Yes | I33: Yes | K33: A | M33: =IF(Table1[[#This Row],[Finished]]="Yes",Table1[[#Headers],[Finished]],IF(Table1[[#This Row],[Review 2 completed]]="Yes",Table1[[#Headers],[Review 2 completed]],IF(Table1[[#This Row],[Ready for review 2]]="Yes",Table1[[#Headers],[Ready for review 2]],IF(Table1[[#This Row],[Review 1 completed]]="Yes",Table1[[#Headers],[Review 1 completed]],IF(Table1[[#This Row],[Ready for review 1]]="Yes",Table1[[#Headers],[Ready for review 1]],IF(Table1[[#This Row],[Early stages]]="Yes",Table1[[#Headers],[Early stages]],"Not started")))))) -> Ready for review 2
A34: 5 | B34: Integration | C34: 3 | D34: Fundamental theorem of calculus | E34: R. Koekoek | F34: Yes | G34: Yes | H34: Yes | K34: A | M34: =IF(Table1[[#This Row],[Finished]]="Yes",Table1[[#Headers],[Finished]],IF(Table1[[#This Row],[Review 2 completed]]="Yes",Table1[[#Headers],[Review 2 completed]],IF(Table1[[#This Row],[Ready for review 2]]="Yes",Table1[[#Headers],[Ready for review 2]],IF(Table1[[#This Row],[Review 1 completed]]="Yes",Table1[[#Headers],[Review 1 completed]],IF(Table1[[#This Row],[Ready for review 1]]="Yes",Table1[[#Headers],[Ready for review 1]],IF(Table1[[#This Row],[Early stages]]="Yes",Table1[[#Headers],[Early stages]],"Not started")))))) -> Review 1 completed
A35: 5 | B35: Integration | C35: 4 | D35: Integration by substitution | E35: R. Koekoek | F35: Yes | G35: Yes | H35: Yes | K35: A | M35: =IF(Table1[[#This Row],[Finished]]="Yes",Table1[[#Headers],[Finished]],IF(Table1[[#This Row],[Review 2 completed]]="Yes",Table1[[#Headers],[Review 2 completed]],IF(Table1[[#This Row],[Ready for review 2]]="Yes",Table1[[#Headers],[Ready for review 2]],IF(Table1[[#This Row],[Review 1 completed]]="Yes",Table1[[#Headers],[Review 1 completed]],IF(Table1[[#This Row],[Ready for review 1]]="Yes",Table1[[#Headers],[Ready for review 1]],IF(Table1[[#This Row],[Early stages]]="Yes",Table1[[#Headers],[Early stages]],"Not started")))))) -> Review 1 completed
A36: 5 | B36: Integration | C36: 5 | D36: Integration by parts | E36: R. Koekoek | F36: Yes | G36: Yes | H36: Yes | K36: A | M36: =IF(Table1[[#This Row],[Finished]]="Yes",Table1[[#Headers],[Finished]],IF(Table1[[#This Row],[Review 2 completed]]="Yes",Table1[[#Headers],[Review 2 completed]],IF(Table1[[#This Row],[Ready for review 2]]="Yes",Table1[[#Headers],[Ready for review 2]],IF(Table1[[#This Row],[Review 1 completed]]="Yes",Table1[[#Headers],[Review 1 completed]],IF(Table1[[#This Row],[Ready for review 1]]="Yes",Table1[[#Headers],[Ready for review 1]],IF(Table1[[#This Row],[Early stages]]="Yes",Table1[[#Headers],[Early stages]],"Not started")))))) -> Review 1 completed
A37: 5 | B37: Integration | C37: 6 | D37: Integration of trigonometric functions | E37: R. Koekoek | F37: Yes | G37: Yes | M37: =IF(Table1[[#This Row],[Finished]]="Yes",Table1[[#Headers],[Finished]],IF(Table1[[#This Row],[Review 2 completed]]="Yes",Table1[[#Headers],[Review 2 completed]],IF(Table1[[#This Row],[Ready for review 2]]="Yes",Table1[[#Headers],[Ready for review 2]],IF(Table1[[#This Row],[Review 1 completed]]="Yes",Table1[[#Headers],[Review 1 completed]],IF(Table1[[#This Row],[Ready for review 1]]="Yes",Table1[[#Headers],[Ready for review 1]],IF(Table1[[#This Row],[Early stages]]="Yes",Table1[[#Headers],[Early stages]],"Not started")))))) -> Ready for review 1
A38: 5 | B38: Integration | C38: 7 | D38: Integration of rational functions | E38: R. Koekoek | F38: Yes | G38: Yes | M38: =IF(Table1[[#This Row],[Finished]]="Yes",Table1[[#Headers],[Finished]],IF(Table1[[#This Row],[Review 2 completed]]="Yes",Table1[[#Headers],[Review 2 completed]],IF(Table1[[#This Row],[Ready for review 2]]="Yes",Table1[[#Headers],[Ready for review 2]],IF(Table1[[#This Row],[Review 1 completed]]="Yes",Table1[[#Headers],[Review 1 completed]],IF(Table1[[#This Row],[Ready for review 1]]="Yes",Table1[[#Headers],[Ready for review 1]],IF(Table1[[#This Row],[Early stages]]="Yes",Table1[[#Headers],[Early stages]],"Not started")))))) -> Ready for review 1
A39: 5 | B39: Integration | C39: 8 | D39: Improper integrals | E39: D. den Ouden-van der Horst | F39: Yes | G39: Yes | H39: Yes | M39: =IF(Table1[[#This Row],[Finished]]="Yes",Table1[[#Headers],[Finished]],IF(Table1[[#This Row],[Review 2 completed]]="Yes",Table1[[#Headers],[Review 2 completed]],IF(Table1[[#This Row],[Ready for review 2]]="Yes",Table1[[#Headers],[Ready for review 2]],IF(Table1[[#This Row],[Review 1 completed]]="Yes",Table1[[#Headers],[Review 1 completed]],IF(Table1[[#This Row],[Ready for review 1]]="Yes",Table1[[#Headers],[Ready for review 1]],IF(Table1[[#This Row],[Early stages]]="Yes",Table1[[#Headers],[Early stages]],"Not started")))))) -> Review 1 completed
A40: 5 | B40: Integration | C40: 9 | D40: Approximating integrals | E40: D. den Ouden-van der Horst | F40: Yes | G40: Yes | M40: =IF(Table1[[#This Row],[Finished]]="Yes",Table1[[#Headers],[Finished]],IF(Table1[[#This Row],[Review 2 completed]]="Yes",Table1[[#Headers],[Review 2 completed]],IF(Table1[[#This Row],[Ready for review 2]]="Yes",Table1[[#Headers],[Ready for review 2]],IF(Table1[[#This Row],[Review 1 completed]]="Yes",Table1[[#Headers],[Review 1 completed]],IF(Table1[[#This Row],[Ready for review 1]]="Yes",Table1[[#Headers],[Ready for review 1]],IF(Table1[[#This Row],[Early stages]]="Yes",Table1[[#Headers],[Early stages]],"Not started")))))) -> Ready for review 1
...
